Workbook

Sheet 0_작성안내
A1: 스마트 생태공장 구축 (전기히터 ↔ 스팀 전환) 현장 세팅·최적화 기록 양식
A2: 주간 스팀 / 야간 전기히터 운전 전환 로직의 파라메터 실측 및 최적화용 현장 기록지. 인쇄하여 현장에서 수기로 작성 후 엑셀에 옮겨 적으면 자동 계산됩니다.
A4: 1. 점검 정보
A5: 현장명
A6: 점검일자
A7: 점검자
A8: 입회자(운전/제어)
A9: Metasys 버전/프로그램
A10: 날씨/외기온도(℃)
A12: 2. 셀 색상 범례
B13: 현장 입력 칸 (노란색) — 여기에만 값을 적습니다.
B14: 자동 계산 칸 (연두색) — 수식, 입력 금지.
B15: 신규 제안 파라메터 (주황색) — 현 UI에 없음, 로직 수정 시 추가 검토.
B16: 예시 행 (회색) — 작성 예시. 실제 기록 시 덮어쓰거나 지우세요.
A17: 파란 글씨 | B17: Metasys 화면 캡처에서 옮겨 적은 현재값(As-found). 현장에서 다시 확인하세요.
A19: 3. 대상 설비 (Metasys UI 기준)
A20: AHU | B20: 구분 | C20: 전기히터 단수 | D20: 급기온도 센서 | E20: 헤더 압력 SP | F20: 헤더 압력계 | G20: 현재 Time Delay | H20: 비고
A21: AHU-G203 | B21: 일반제동 | C21: 6 | D21: 1 | E21: 10 | F21: PRE-1, PRE-2 | G21: 5
A22: AHU-G204 | B22: 일반제동 | C22: 6 | D22: 1 | E22: 10 | F22: PRE-1, PRE-2 | G22: 5 | H22: 캡처 시 Override 운전
A23: AHU-G213 | B23: 일반제동 | C23: 6 | D23: 1 | E23: 10 | F23: PRE-1, PRE-2 | G23: 10
A24: AHU-G301 | B24: 일반제동 | C24: 8 | D24: 2 | E24: 10 | F24: PRE-1, PRE-2 | G24: 1 | H24: 캡처 시 Override 운전. 히터 #1그룹 4단 + #2그룹 4단, Supply Temp-1/-2
A25: AHU-G107 | B25: 세파제동 | C25: 6 | D25: 1 | E25: 7 | F25: 헤더 1개 | G25: 1 | H25: 캡처 시 Override(강제) 운전. 스팀 공급 헤더온도 센서 별도
A27: 4. 시트 구성 및 권장 작성 순서
A28: 시트 | C28: 내용
A29: 1_파라메터기록 | C29: 현재 세팅값(As-found) 확인 → 조정 후 값(As-left) 기록. 현장 계기 vs UI 비교.
A30: 2_밸브상태 | C30: AHU별 [게이트-자동밸브-게이트]+바이패스 상태를 전기모드/스팀모드 각각 기록. 밸브 사양·스트로크 실측.
A31: 3_전환시간실측 | C31: 전기→스팀, 스팀→전기 전환 시 각 이벤트 시각(hh:mm:ss) 기록 → 지연시간·열공백·권장 Time Delay 자동 계산.
A32: 4_초기개도_트렌드 | C32: 밸브 초기개도/램프율 시험 시 1분 간격 트렌드 기록 → 급기온도 상승률 자동 판정 (보관소 급승온 방지).
A33: 5_초기개도_매트릭스 | C33: 설정온도 × 초기개도율 조합별 결과 요약 → 최적 초기개도율 결정.
A34: 6_추가체크리스트 | C34: 계측·로직·스팀계통·히터안전·보관소환경·페일세이프·에너지 점검항목.
A35: 7_로직개선제안 | C35: Metasys 로직 수정 시 추가할 파라메터 제안값과 현장 결정값.
A36: 8_최종세팅값 | C36: AHU별 최종 확정값 요약 (실측 시트에서 자동 집계) 및 확인 서명.
A38: 5. 시험 시 안전 수칙 (보관소)
A39: ① 시험 전 보관소 담당자에게 시험 시간 통보, 보관소 허용 온·습도 범위 확인 후 '4_초기개도_트렌드' 상단 허용값에 기입.
A40: ② 첫 스팀 전환 시험은 자동밸브 수동 지령으로 낮은 개도(예: 10%)부터 시작, 급기온도 상승률이 허용치 초과 시 즉시 개도 낮춤.
A41: ③ 전환 시험은 AHU 1대씩 순차 진행 (동시 전환 시 헤더 압력 강하로 다른 AHU가 연쇄 전환될 수 있음).
A42: ④ 수동 오버라이드(밸브 수동 지령, SRC 강제 등)는 시험 종료 후 반드시 자동으로 원복 — '6_추가체크리스트' 원복 항목 체크.
A43: ⑤ 바이패스 밸브는 시험 중 '닫힘' 유지. 바이패스 개방 상태에서는 자동밸브 제어가 무의미함.

Sheet 1_파라메터기록
A1: 1. 시스템 파라메터 기록 (As-found / As-left)
A2: As-found = 점검 시작 시 UI 표시값(파란 글씨는 캡처 화면값, 현장 재확인). As-left = 조정 후 최종값. 주황색 행은 현재 UI에 없는 신규 제안 항목('7_로직개선제안' 참조).
A4: No | B4: 구분 | C4: 파라메터 | D4: 단위 | E4: AHU-G203 (일반제동) | G4: AHU-G204 (일반제동) | I4: AHU-G213 (일반제동) | K4: AHU-G301 (일반제동) | M4: AHU-G107 (세파제동) | O4: 비고 / 확인사항
E5: As-found | F5: As-left | G5: As-found | H5: As-left | I5: As-found | J5: As-left | K5: As-found | L5: As-left | M5: As-found | N5: As-left
A6: 1 | B6: 헤더 | C6: Pressure Setpoint (스팀 전환 압력) | D6: bar | E6: 10 | G6: 10 | I6: 10 | K6: 10 | M6: 7 | O6: 일반제동 10.0은 미세팅 임시값(헤더 최고 약 8 bar → 현재값으론 전환 안 됨). 하단 압력 프로파일로 결정
A7: 2 | B7: 헤더 | C7: 헤더 압력 PRE-1 (UI 표시) | D7: bar | E7: 7.9 | G7: 7.9 | I7: 7.9 | K7: 7.9 | M7: 8 | O7: 점검 시각의 순간값
A8: 3 | B8: 헤더 | C8: 헤더 압력 PRE-2 (UI 표시) | D8: bar | E8: 7.8 | G8: 7.8 | I8: 7.8 | K8: 7.8 | O8: 세파제동은 압력계 1개
A9: 4 | B9: 헤더 | C9: 헤더 압력 현장 압력계 지시값 | D9: bar | O9: UI와 편차 0.2 bar 초과 시 교정 검토
A10: 5 | B10: 헤더 | C10: 스팀 공급 헤더 온도 (UI) | D10: ℃ | M10: 24.6 | O10: 세파제동만 표시
A11: 6 | B11: AHU | C11: SRC Enable (표시 색상 포함) | D11: - | E11: Enable(녹색) | G11: Override(주황) | I11: Enable(녹색) | K11: Override(주황) | M11: Override(주황) | O11: 녹색 = Enable(정상 가동) / 주황 = Override Operation. 시험 후 Enable 원복
A12: 7 | B12: AHU | C12: Diff Setpoint | D12: ℃ | E12: 0.5 | G12: 0.5 | I12: 0.5 | K12: 0.5 | M12: 0.5
A13: 8 | B13: AHU | C13: Time Delay | D13: 초/분 | E13: 5 | G13: 5 | I13: 10 | K13: 1 | M13: 1 | O13: 미세팅 — 이번 실측(3_전환시간실측 권장값)으로 결정. 입력 단위 확인
A14: 9 | B14: AHU | C14: 급기온도 설정값(SP) | D14: ℃ | O14: UI 미표시 — 프로그램에서 확인
A15: 10 | B15: AHU | C15: Supply Temp (-1) | D15: ℃ | E15: 23.7 | G15: 22.1 | I15: 17.7 | K15: 21.1 | M15: 19.1
A16: 11 | B16: AHU | C16: Supply Temp-2 | D16: ℃ | K16: 21 | O16: G301만 해당
A17: 12 | B17: AHU | C17: 급기온도 현장 측정값 | D17: ℃ | O17: UI와 편차 0.5℃ 초과 시 센서 점검
A18: 13 | B18: AHU | C18: 보관소(실내) 온도 / 습도 | D18: ℃ / % | O18: 예: 20.5 / 45
A19: 14 | B19: AHU | C19: Alarm 상태 | D19: - | E19: Normal | G19: Normal | I19: Normal | K19: Normal | M19: Normal
A20: 15 | B20: AHU | C20: 전기히터 Command ON 단수 | D20: 단 | E20: 0 | G20: 0 | I20: 6 | K20: 8 | M20: 5 | O20: Command와 Status 피드백 일치 여부
A21: 16 | B21: AHU | C21: 자동밸브 지령 / 피드백 | D21: % | O21: 예: 0 / 0
A22: 17 | B22: 신규 | C22: 압력 히스테리시스 (복귀 압력) | D22: bar | O22: P02
A23: 18 | B23: 신규 | C23: 압력 확인 지연시간 | D23: 초 | O23: P03
A24: 19 | B24: 신규 | C24: 밸브 초기개도 | D24: % | O24: P04 — 5_초기개도_매트릭스 결과
A25: 20 | B25: 신규 | C25: 밸브 램프율 | D25: %/분 | O25: P05
A26: 21 | B26: 신규 | C26: 전환 중 최대개도 제한 | D26: % | O26: P06
A27: 22 | B27: 신규 | C27: 히터 단계 OFF 간격 | D27: 초/단 | O27: P08
A28: 23 | B28: 신규 | C28: 최소 모드 유지시간 | D28: 분 | O28: P10
A29: 24 | B29: 신규 | C29: AHU 순차 전환 간격 | D29: 초 | O29: P11
A30: 25 | B30: 신규 | C30: 스팀 실패 판정 → 전기 복귀 조건 | D30: - | O30: P12
A31: 26 | B31: 신규 | C31: 급기온도 상승률 제한 | D31: ℃/분 | O31: P14
A33: ※ G301은 Supply Temp-1/-2 및 히터 #1그룹(4단)·#2그룹(4단)으로 구성 — 비고란에 그룹별 기록.
A35: 1-1. 헤더 압력 시간대별 기록 (Pressure Setpoint 결정용)
A36: 일반제동 SP 10.0 bar는 미세팅 임시값이며 헤더 최고 압력이 약 8 bar이므로, 아래 기록으로 주간에 안정적으로 유지되는 압력을 확인해 SP를 정합니다.
B37: 시각 | C37: 일반 PRE-1 (bar) | D37: 일반 PRE-2 (bar) | E37: 세파 헤더 (bar) | F37: 세파 헤더온도 (℃) | G37: 보일러 운전 대수 | H37: 비고
B38: 06:00
B39: 07:00
B40: 08:00
B41: 09:00
B42: 10:00
B43: 11:00
...

Sheet 2_밸브상태
A1: 2. 스팀 밸브 상태 점검 — [V1 게이트 – MV 자동밸브(Metasys) – V2 게이트] + BV 바이패스
A2: 정상 구성: V1 열림 · V2 열림 · BV 닫힘. 전기모드에서 MV 피드백은 닫힘(≤ 허용값), 스팀모드에서 지령-피드백 편차 ≤ 허용값. 코일 전·후 온도는 전기모드에서 스팀 누설(밸브 패싱) 확인용.
A3: 판정 기준 | B3: 닫힘 허용(%) | C3: 2 | D3: 편차 허용(%) | E3: 5 | F3: ← 기준값 가정치, 현장 협의 후 수정
A5: AHU | B5: 점검 모드 | C5: 점검 시각 | D5: V1 상류 게이트밸브 | E5: MV 자동밸브 지령(%) | F5: MV 피드백(%) | G5: MV 현장 지시눈금(%) | H5: V2 하류 게이트밸브 | I5: BV 바이패스 게이트밸브 | J5: 액추에이터 수동/자동 | K5: 스팀트랩 상태 | L5: 스트레이너 | M5: 코일 전·후 온도(℃) | N5: 구성 판정 | O5: 개도 판정 | P5: 비고
A6: AHU-G213 | B6: 전기모드 | D6: 열림 | E6: 0 | F6: 0 | G6: 0 | H6: 열림 | I6: 닫힘 | J6: 자동 | K6: 정상 | L6: 정상 | M6: 15.2 / 15.4 | N6: =IF(COUNTA(D6,H6,I6)<3,"",IF(AND(D6="열림",H6="열림",I6="닫힘"),"정상",IF(I6<>"닫힘","바이패스 개방!","게이트 확인"))) -> 정상 | O6: =IF(F6="","",IF(B6="전기모드",IF(F6<=$C$3,"정상(닫힘)","패싱/미닫힘 확인"),IF(E6="","",IF(ABS(E6-F6)<=$E$3,"정상","지령-피드백 편차")))) -> 정상(닫힘) | P6: 예시
A7: AHU-G203 | B7: 전기모드 | N7: =IF(COUNTA(D7,H7,I7)<3,"",IF(AND(D7="열림",H7="열림",I7="닫힘"),"정상",IF(I7<>"닫힘","바이패스 개방!","게이트 확인"))) | O7: =IF(F7="","",IF(B7="전기모드",IF(F7<=$C$3,"정상(닫힘)","패싱/미닫힘 확인"),IF(E7="","",IF(ABS(E7-F7)<=$E$3,"정상","지령-피드백 편차"))))
A8: AHU-G203 | B8: 스팀모드 | N8: =IF(COUNTA(D8,H8,I8)<3,"",IF(AND(D8="열림",H8="열림",I8="닫힘"),"정상",IF(I8<>"닫힘","바이패스 개방!","게이트 확인"))) | O8: =IF(F8="","",IF(B8="전기모드",IF(F8<=$C$3,"정상(닫힘)","패싱/미닫힘 확인"),IF(E8="","",IF(ABS(E8-F8)<=$E$3,"정상","지령-피드백 편차"))))
A9: AHU-G204 | B9: 전기모드 | N9: =IF(COUNTA(D9,H9,I9)<3,"",IF(AND(D9="열림",H9="열림",I9="닫힘"),"정상",IF(I9<>"닫힘","바이패스 개방!","게이트 확인"))) | O9: =IF(F9="","",IF(B9="전기모드",IF(F9<=$C$3,"정상(닫힘)","패싱/미닫힘 확인"),IF(E9="","",IF(ABS(E9-F9)<=$E$3,"정상","지령-피드백 편차"))))
A10: AHU-G204 | B10: 스팀모드 | N10: =IF(COUNTA(D10,H10,I10)<3,"",IF(AND(D10="열림",H10="열림",I10="닫힘"),"정상",IF(I10<>"닫힘","바이패스 개방!","게이트 확인"))) | O10: =IF(F10="","",IF(B10="전기모드",IF(F10<=$C$3,"정상(닫힘)","패싱/미닫힘 확인"),IF(E10="","",IF(ABS(E10-F10)<=$E$3,"정상","지령-피드백 편차"))))
A11: AHU-G213 | B11: 전기모드 | N11: =IF(COUNTA(D11,H11,I11)<3,"",IF(AND(D11="열림",H11="열림",I11="닫힘"),"정상",IF(I11<>"닫힘","바이패스 개방!","게이트 확인"))) | O11: =IF(F11="","",IF(B11="전기모드",IF(F11<=$C$3,"정상(닫힘)","패싱/미닫힘 확인"),IF(E11="","",IF(ABS(E11-F11)<=$E$3,"정상","지령-피드백 편차"))))
A12: AHU-G213 | B12: 스팀모드 | N12: =IF(COUNTA(D12,H12,I12)<3,"",IF(AND(D12="열림",H12="열림",I12="닫힘"),"정상",IF(I12<>"닫힘","바이패스 개방!","게이트 확인"))) | O12: =IF(F12="","",IF(B12="전기모드",IF(F12<=$C$3,"정상(닫힘)","패싱/미닫힘 확인"),IF(E12="","",IF(ABS(E12-F12)<=$E$3,"정상","지령-피드백 편차"))))
A13: AHU-G301 | B13: 전기모드 | N13: =IF(COUNTA(D13,H13,I13)<3,"",IF(AND(D13="열림",H13="열림",I13="닫힘"),"정상",IF(I13<>"닫힘","바이패스 개방!","게이트 확인"))) | O13: =IF(F13="","",IF(B13="전기모드",IF(F13<=$C$3,"정상(닫힘)","패싱/미닫힘 확인"),IF(E13="","",IF(ABS(E13-F13)<=$E$3,"정상","지령-피드백 편차"))))
A14: AHU-G301 | B14: 스팀모드 | N14: =IF(COUNTA(D14,H14,I14)<3,"",IF(AND(D14="열림",H14="열림",I14="닫힘"),"정상",IF(I14<>"닫힘","바이패스 개방!","게이트 확인"))) | O14: =IF(F14="","",IF(B14="전기모드",IF(F14<=$C$3,"정상(닫힘)","패싱/미닫힘 확인"),IF(E14="","",IF(ABS(E14-F14)<=$E$3,"정상","지령-피드백 편차"))))
A15: AHU-G107 | B15: 전기모드 | N15: =IF(COUNTA(D15,H15,I15)<3,"",IF(AND(D15="열림",H15="열림",I15="닫힘"),"정상",IF(I15<>"닫힘","바이패스 개방!","게이트 확인"))) | O15: =IF(F15="","",IF(B15="전기모드",IF(F15<=$C$3,"정상(닫힘)","패싱/미닫힘 확인"),IF(E15="","",IF(ABS(E15-F15)<=$E$3,"정상","지령-피드백 편차"))))
A16: AHU-G107 | B16: 스팀모드 | N16: =IF(COUNTA(D16,H16,I16)<3,"",IF(AND(D16="열림",H16="열림",I16="닫힘"),"정상",IF(I16<>"닫힘","바이패스 개방!","게이트 확인"))) | O16: =IF(F16="","",IF(B16="전기모드",IF(F16<=$C$3,"정상(닫힘)","패싱/미닫힘 확인"),IF(E16="","",IF(ABS(E16-F16)<=$E$3,"정상","지령-피드백 편차"))))
A19: 2-1. 자동밸브(MV) 사양 및 스트로크 실측
A20: AHU | B20: 밸브 TAG | C20: 구경(A) | D20: 액추에이터 모델 | E20: 제어신호 (0-10V/4-20mA) | F20: Fail 위치 (NC/NO/Last) | G20: 사양 스트로크 시간(초) | H20: 실측 0→100% (초) | I20: 실측 100→0% (초) | J20: 최소 제어 개도(%) | K20: V1·V2 게이트 구경(A) | L20: BV 바이패스 구경(A) | M20: 스트로크 편차(%) | N20: 판정 | P20: 비고
A21: AHU-G203 | M21: =IF(OR(G21="",H21=""),"",(H21-G21)/G21) | N21: =IF(M21="","",IF(ABS(M21)<=0.2,"정상","스트로크 점검"))
A22: AHU-G204 | M22: =IF(OR(G22="",H22=""),"",(H22-G22)/G22) | N22: =IF(M22="","",IF(ABS(M22)<=0.2,"정상","스트로크 점검"))
A23: AHU-G213 | M23: =IF(OR(G23="",H23=""),"",(H23-G23)/G23) | N23: =IF(M23="","",IF(ABS(M23)<=0.2,"정상","스트로크 점검"))
A24: AHU-G301 | M24: =IF(OR(G24="",H24=""),"",(H24-G24)/G24) | N24: =IF(M24="","",IF(ABS(M24)<=0.2,"정상","스트로크 점검"))
A25: AHU-G107 | M25: =IF(OR(G25="",H25=""),"",(H25-G25)/G25) | N25: =IF(M25="","",IF(ABS(M25)<=0.2,"정상","스트로크 점검"))
A26: ※ 스트로크 편차 ±20% 초과 시 액추에이터/링키지 점검 (기준은 가정치). Fail 위치는 정전·통신장애 시 보관소 안전과 직결 — NC(정상닫힘) 권장.

Sheet 3_전환시간실측
A1: 3. 모드 전환 시간 실측 (시각은 hh:mm:ss 로 입력, 예: 14:05:30)
A2: Metasys 트렌드(1~5초 간격 권장) 또는 스톱워치로 각 이벤트 시각을 기록. 지연시간(초)은 자동 계산. 열공백(+) = 히터 OFF 후 스팀 열이 도달하기 전까지 열 공급이 없는 시간 / 중첩(−) = 둘 다 가열 중.
A3: Time Delay 여유 | C3: 30 | D3: ← 권장 Time Delay = (스팀 열도달 시각 − 전환신호 시각) + 여유. 여유값은 가정치.
A5: A. 전기 → 스팀 전환 (헤더압력 ≥ SP)
A6: AHU | B6: 시험 No | C6: 날짜 | D6: T0 헤더압력 SP 도달 | E6: T1 SRC 전환신호 | F6: T2 MV 개도지령 | G6: T3 MV 실제 동작시작 | H6: T4 급기온도 상승시작(열도달) | I6: T5 히터 OFF 지령 | J6: T6 히터 실제 OFF(전류 0) | K6: T7 급기온도 안정(SP±Diff) | L6: 압력→신호 (T1−T0) | M6: 밸브 응답 (T3−T2) | N6: 열전달 지연 (T4−T3) | O6: 스팀 총응답 (T4−T1) | P6: 히터 응답 (T6−T5) | Q6: 열공백(+)/ 중첩(−) (T4−T6) | R6: 안정화 (T7−T1) | S6: 권장 Time Delay | T6: 전환 중 최저 급기온도(℃) | U6: MV 개도율 (T4 시점 %) | V6: 비고
A7: AHU-G213 | B7: 1 | D7: 0.58333333 | E7: 0.5833912 | F7: 0.5833912 | G7: 0.58342593 | H7: 0.58449074 | I7: 0.58344907 | J7: 0.58346065 | K7: 0.58784722 | L7: =IF(OR(E7="",D7=""),"",ROUND((E7-D7)*86400,0)) -> 5 | M7: =IF(OR(G7="",F7=""),"",ROUND((G7-F7)*86400,0)) -> 3 | N7: =IF(OR(H7="",G7=""),"",ROUND((H7-G7)*86400,0)) -> 92 | O7: =IF(OR(H7="",E7=""),"",ROUND((H7-E7)*86400,0)) -> 95 | P7: =IF(OR(J7="",I7=""),"",ROUND((J7-I7)*86400,0)) -> 1 | Q7: =IF(OR(H7="",J7=""),"",ROUND((H7-J7)*86400,0)) -> 89 | R7: =IF(OR(K7="",E7=""),"",ROUND((K7-E7)*86400,0)) -> 385 | S7: =IF(OR(H7="",E7=""),"",ROUND((H7-E7)*86400,0)+$C$3) -> 125 | T7: 16.2 | U7: 25 | V7: 예시: 1단 OFF 후 전체 OFF
L8: =IF(OR(E8="",D8=""),"",ROUND((E8-D8)*86400,0)) | M8: =IF(OR(G8="",F8=""),"",ROUND((G8-F8)*86400,0)) | N8: =IF(OR(H8="",G8=""),"",ROUND((H8-G8)*86400,0)) | O8: =IF(OR(H8="",E8=""),"",ROUND((H8-E8)*86400,0)) | P8: =IF(OR(J8="",I8=""),"",ROUND((J8-I8)*86400,0)) | Q8: =IF(OR(H8="",J8=""),"",ROUND((H8-J8)*86400,0)) | R8: =IF(OR(K8="",E8=""),"",ROUND((K8-E8)*86400,0)) | S8: =IF(OR(H8="",E8=""),"",ROUND((H8-E8)*86400,0)+$C$3)
L9: =IF(OR(E9="",D9=""),"",ROUND((E9-D9)*86400,0)) | M9: =IF(OR(G9="",F9=""),"",ROUND((G9-F9)*86400,0)) | N9: =IF(OR(H9="",G9=""),"",ROUND((H9-G9)*86400,0)) | O9: =IF(OR(H9="",E9=""),"",ROUND((H9-E9)*86400,0)) | P9: =IF(OR(J9="",I9=""),"",ROUND((J9-I9)*86400,0)) | Q9: =IF(OR(H9="",J9=""),"",ROUND((H9-J9)*86400,0)) | R9: =IF(OR(K9="",E9=""),"",ROUND((K9-E9)*86400,0)) | S9: =IF(OR(H9="",E9=""),"",ROUND((H9-E9)*86400,0)+$C$3)
L10: =IF(OR(E10="",D10=""),"",ROUND((E10-D10)*86400,0)) | M10: =IF(OR(G10="",F10=""),"",ROUND((G10-F10)*86400,0)) | N10: =IF(OR(H10="",G10=""),"",ROUND((H10-G10)*86400,0)) | O10: =IF(OR(H10="",E10=""),"",ROUND((H10-E10)*86400,0)) | P10: =IF(OR(J10="",I10=""),"",ROUND((J10-I10)*86400,0)) | Q10: =IF(OR(H10="",J10=""),"",ROUND((H10-J10)*86400,0)) | R10: =IF(OR(K10="",E10=""),"",ROUND((K10-E10)*86400,0)) | S10: =IF(OR(H10="",E10=""),"",ROUND((H10-E10)*86400,0)+$C$3)
L11: =IF(OR(E11="",D11=""),"",ROUND((E11-D11)*86400,0)) | M11: =IF(OR(G11="",F11=""),"",ROUND((G11-F11)*86400,0)) | N11: =IF(OR(H11="",G11=""),"",ROUND((H11-G11)*86400,0)) | O11: =IF(OR(H11="",E11=""),"",ROUND((H11-E11)*86400,0)) | P11: =IF(OR(J11="",I11=""),"",ROUND((J11-I11)*86400,0)) | Q11: =IF(OR(H11="",J11=""),"",ROUND((H11-J11)*86400,0)) | R11: =IF(OR(K11="",E11=""),"",ROUND((K11-E11)*86400,0)) | S11: =IF(OR(H11="",E11=""),"",ROUND((H11-E11)*86400,0)+$C$3)
L12: =IF(OR(E12="",D12=""),"",ROUND((E12-D12)*86400,0)) | M12: =IF(OR(G12="",F12=""),"",ROUND((G12-F12)*86400,0)) | N12: =IF(OR(H12="",G12=""),"",ROUND((H12-G12)*86400,0)) | O12: =IF(OR(H12="",E12=""),"",ROUND((H12-E12)*86400,0)) | P12: =IF(OR(J12="",I12=""),"",ROUND((J12-I12)*86400,0)) | Q12: =IF(OR(H12="",J12=""),"",ROUND((H12-J12)*86400,0)) | R12: =IF(OR(K12="",E12=""),"",ROUND((K12-E12)*86400,0)) | S12: =IF(OR(H12="",E12=""),"",ROUND((H12-E12)*86400,0)+$C$3)
L13: =IF(OR(E13="",D13=""),"",ROUND((E13-D13)*86400,0)) | M13: =IF(OR(G13="",F13=""),"",ROUND((G13-F13)*86400,0)) | N13: =IF(OR(H13="",G13=""),"",ROUND((H13-G13)*86400,0)) | O13: =IF(OR(H13="",E13=""),"",ROUND((H13-E13)*86400,0)) | P13: =IF(OR(J13="",I13=""),"",ROUND((J13-I13)*86400,0)) | Q13: =IF(OR(H13="",J13=""),"",ROUND((H13-J13)*86400,0)) | R13: =IF(OR(K13="",E13=""),"",ROUND((K13-E13)*86400,0)) | S13: =IF(OR(H13="",E13=""),"",ROUND((H13-E13)*86400,0)+$C$3)
L14: =IF(OR(E14="",D14=""),"",ROUND((E14-D14)*86400,0)) | M14: =IF(OR(G14="",F14=""),"",ROUND((G14-F14)*86400,0)) | N14: =IF(OR(H14="",G14=""),"",ROUND((H14-G14)*86400,0)) | O14: =IF(OR(H14="",E14=""),"",ROUND((H14-E14)*86400,0)) | P14: =IF(OR(J14="",I14=""),"",ROUND((J14-I14)*86400,0)) | Q14: =IF(OR(H14="",J14=""),"",ROUND((H14-J14)*86400,0)) | R14: =IF(OR(K14="",E14=""),"",ROUND((K14-E14)*86400,0)) | S14: =IF(OR(H14="",E14=""),"",ROUND((H14-E14)*86400,0)+$C$3)
L15: =IF(OR(E15="",D15=""),"",ROUND((E15-D15)*86400,0)) | M15: =IF(OR(G15="",F15=""),"",ROUND((G15-F15)*86400,0)) | N15: =IF(OR(H15="",G15=""),"",ROUND((H15-G15)*86400,0)) | O15: =IF(OR(H15="",E15=""),"",ROUND((H15-E15)*86400,0)) | P15: =IF(OR(J15="",I15=""),"",ROUND((J15-I15)*86400,0)) | Q15: =IF(OR(H15="",J15=""),"",ROUND((H15-J15)*86400,0)) | R15: =IF(OR(K15="",E15=""),"",ROUND((K15-E15)*86400,0)) | S15: =IF(OR(H15="",E15=""),"",ROUND((H15-E15)*86400,0)+$C$3)
L16: =IF(OR(E16="",D16=""),"",ROUND((E16-D16)*86400,0)) | M16: =IF(OR(G16="",F16=""),"",ROUND((G16-F16)*86400,0)) | N16: =IF(OR(H16="",G16=""),"",ROUND((H16-G16)*86400,0)) | O16: =IF(OR(H16="",E16=""),"",ROUND((H16-E16)*86400,0)) | P16: =IF(OR(J16="",I16=""),"",ROUND((J16-I16)*86400,0)) | Q16: =IF(OR(H16="",J16=""),"",ROUND((H16-J16)*86400,0)) | R16: =IF(OR(K16="",E16=""),"",ROUND((K16-E16)*86400,0)) | S16: =IF(OR(H16="",E16=""),"",ROUND((H16-E16)*86400,0)+$C$3)
L17: =IF(OR(E17="",D17=""),"",ROUND((E17-D17)*86400,0)) | M17: =IF(OR(G17="",F17=""),"",ROUND((G17-F17)*86400,0)) | N17: =IF(OR(H17="",G17=""),"",ROUND((H17-G17)*86400,0)) | O17: =IF(OR(H17="",E17=""),"",ROUND((H17-E17)*86400,0)) | P17: =IF(OR(J17="",I17=""),"",ROUND((J17-I17)*86400,0)) | Q17: =IF(OR(H17="",J17=""),"",ROUND((H17-J17)*86400,0)) | R17: =IF(OR(K17="",E17=""),"",ROUND((K17-E17)*86400,0)) | S17: =IF(OR(H17="",E17=""),"",ROUND((H17-E17)*86400,0)+$C$3)
L18: =IF(OR(E18="",D18=""),"",ROUND((E18-D18)*86400,0)) | M18: =IF(OR(G18="",F18=""),"",ROUND((G18-F18)*86400,0)) | N18: =IF(OR(H18="",G18=""),"",ROUND((H18-G18)*86400,0)) | O18: =IF(OR(H18="",E18=""),"",ROUND((H18-E18)*86400,0)) | P18: =IF(OR(J18="",I18=""),"",ROUND((J18-I18)*86400,0)) | Q18: =IF(OR(H18="",J18=""),"",ROUND((H18-J18)*86400,0)) | R18: =IF(OR(K18="",E18=""),"",ROUND((K18-E18)*86400,0)) | S18: =IF(OR(H18="",E18=""),"",ROUND((H18-E18)*86400,0)+$C$3)
L19: =IF(OR(E19="",D19=""),"",ROUND((E19-D19)*86400,0)) | M19: =IF(OR(G19="",F19=""),"",ROUND((G19-F19)*86400,0)) | N19: =IF(OR(H19="",G19=""),"",ROUND((H19-G19)*86400,0)) | O19: =IF(OR(H19="",E19=""),"",ROUND((H19-E19)*86400,0)) | P19: =IF(OR(J19="",I19=""),"",ROUND((J19-I19)*86400,0)) | Q19: =IF(OR(H19="",J19=""),"",ROUND((H19-J19)*86400,0)) | R19: =IF(OR(K19="",E19=""),"",ROUND((K19-E19)*86400,0)) | S19: =IF(OR(H19="",E19=""),"",ROUND((H19-E19)*86400,0)+$C$3)
... L21: =IF(OR(E21="",D21=""),"",ROUND((E21-D21)*86400,0)) | M21: =IF(OR(G21="",F21=""),"",ROUND((G21-F21)*86400,0)) | N21: =IF(OR(H21="",G21=""),"",ROUND((H21-G21)*86400,0)) | O21: =IF(OR(H21="",E21=""),"",ROUND((H21-E21)*86400,0)) | P21: =IF(OR(J21="",I21=""),"",ROUND((J21-I21)*86400,0)) | Q21: =IF(OR(H21="",J21=""),"",ROUND((H21-J21)*86400,0)) | R21: =IF(OR(K21="",E21=""),"",ROUND((K21-E21)*86400,0)) | S21: =IF(OR(H21="",E21=""),"",ROUND((H21-E21)*86400,0)+$C$3)
A24: B. 스팀 → 전기 전환 (헤더압력 < SP 또는 야간 전환)
A25: AHU | B25: 시험 No | C25: 날짜 | D25: T0 헤더압력 SP 미만 | E25: T1 SRC 전환신호 | F25: T2 히터 ON 지령 | G25: T3 히터 실제 ON(전류 확인) | H25: T4 MV 닫힘지령 | I25: T5 MV 완전닫힘(피드백0) | J25: T6 코일 후단 온도 하강시작 | K25: T7 급기온도 안정(SP±Diff) | L25: 압력→신호 (T1−T0) | M25: 히터 응답 (T3−T2) | N25: 밸브 닫힘 (T5−T4) | O25: 중첩시간 (T5−T3) | P25: 히터ON→밸브지령 (T4−T3) | Q25: 잔열 지속 (T6−T5) | R25: 안정화 (T7−T1) | S25: 최고 급기 오버슈트(℃) | T25: 전환 중 최고 급기온도(℃) | U25: 급기온도 SP(℃) | V25: 비고
A26: AHU-G213 | B26: 1 | D26: 0.75 | E26: 0.75005787 | F26: 0.75005787 | G26: 0.75008102 | H26: 0.75040509 | I26: 0.75081019 | J26: 0.75115741 | K26: 0.75347222 | L26: =IF(OR(E26="",D26=""),"",ROUND((E26-D26)*86400,0)) -> 5 | M26: =IF(OR(G26="",F26=""),"",ROUND((G26-F26)*86400,0)) -> 2 | N26: =IF(OR(I26="",H26=""),"",ROUND((I26-H26)*86400,0)) -> 35 | O26: =IF(OR(I26="",G26=""),"",ROUND((I26-G26)*86400,0)) -> 63 | P26: =IF(OR(H26="",G26=""),"",ROUND((H26-G26)*86400,0)) -> 28 | Q26: =IF(OR(J26="",I26=""),"",ROUND((J26-I26)*86400,0)) -> 30 | R26: =IF(OR(K26="",E26=""),"",ROUND((K26-E26)*86400,0)) -> 295 | S26: =IF(OR(T26="",U26=""),"",T26-U26) -> 2.1 | T26: 24.1 | U26: 22 | V26: 예시: 히터 6단 동시 ON
L27: =IF(OR(E27="",D27=""),"",ROUND((E27-D27)*86400,0)) | M27: =IF(OR(G27="",F27=""),"",ROUND((G27-F27)*86400,0)) | N27: =IF(OR(I27="",H27=""),"",ROUND((I27-H27)*86400,0)) | O27: =IF(OR(I27="",G27=""),"",ROUND((I27-G27)*86400,0)) | P27: =IF(OR(H27="",G27=""),"",ROUND((H27-G27)*86400,0)) | Q27: =IF(OR(J27="",I27=""),"",ROUND((J27-I27)*86400,0)) | R27: =IF(OR(K27="",E27=""),"",ROUND((K27-E27)*86400,0)) | S27: =IF(OR(T27="",U27=""),"",T27-U27)
L28: =IF(OR(E28="",D28=""),"",ROUND((E28-D28)*86400,0)) | M28: =IF(OR(G28="",F28=""),"",ROUND((G28-F28)*86400,0)) | N28: =IF(OR(I28="",H28=""),"",ROUND((I28-H28)*86400,0)) | O28: =IF(OR(I28="",G28=""),"",ROUND((I28-G28)*86400,0)) | P28: =IF(OR(H28="",G28=""),"",ROUND((H28-G28)*86400,0)) | Q28: =IF(OR(J28="",I28=""),"",ROUND((J28-I28)*86400,0)) | R28: =IF(OR(K28="",E28=""),"",ROUND((K28-E28)*86400,0)) | S28: =IF(OR(T28="",U28=""),"",T28-U28)
L29: =IF(OR(E29="",D29=""),"",ROUND((E29-D29)*86400,0)) | M29: =IF(OR(G29="",F29=""),"",ROUND((G29-F29)*86400,0)) | N29: =IF(OR(I29="",H29=""),"",ROUND((I29-H29)*86400,0)) | O29: =IF(OR(I29="",G29=""),"",ROUND((I29-G29)*86400,0)) | P29: =IF(OR(H29="",G29=""),"",ROUND((H29-G29)*86400,0)) | Q29: =IF(OR(J29="",I29=""),"",ROUND((J29-I29)*86400,0)) | R29: =IF(OR(K29="",E29=""),"",ROUND((K29-E29)*86400,0)) | S29: =IF(OR(T29="",U29=""),"",T29-U29)
L30: =IF(OR(E30="",D30=""),"",ROUND((E30-D30)*86400,0)) | M30: =IF(OR(G30="",F30=""),"",ROUND((G30-F30)*86400,0)) | N30: =IF(OR(I30="",H30=""),"",ROUND((I30-H30)*86400,0)) | O30: =IF(OR(I30="",G30=""),"",ROUND((I30-G30)*86400,0)) | P30: =IF(OR(H30="",G30=""),"",ROUND((H30-G30)*86400,0)) | Q30: =IF(OR(J30="",I30=""),"",ROUND((J30-I30)*86400,0)) | R30: =IF(OR(K30="",E30=""),"",ROUND((K30-E30)*86400,0)) | S30: =IF(OR(T30="",U30=""),"",T30-U30)
L31: =IF(OR(E31="",D31=""),"",ROUND((E31-D31)*86400,0)) | M31: =IF(OR(G31="",F31=""),"",ROUND((G31-F31)*86400,0)) | N31: =IF(OR(I31="",H31=""),"",ROUND((I31-H31)*86400,0)) | O31: =IF(OR(I31="",G31=""),"",ROUND((I31-G31)*86400,0)) | P31: =IF(OR(H31="",G31=""),"",ROUND((H31-G31)*86400,0)) | Q31: =IF(OR(J31="",I31=""),"",ROUND((J31-I31)*86400,0)) | R31: =IF(OR(K31="",E31=""),"",ROUND((K31-E31)*86400,0)) | S31: =IF(OR(T31="",U31=""),"",T31-U31)
L32: =IF(OR(E32="",D32=""),"",ROUND((E32-D32)*86400,0)) | M32: =IF(OR(G32="",F32=""),"",ROUND((G32-F32)*86400,0)) | N32: =IF(OR(I32="",H32=""),"",ROUND((I32-H32)*86400,0)) | O32: =IF(OR(I32="",G32=""),"",ROUND((I32-G32)*86400,0)) | P32: =IF(OR(H32="",G32=""),"",ROUND((H32-G32)*86400,0)) | Q32: =IF(OR(J32="",I32=""),"",ROUND((J32-I32)*86400,0)) | R32: =IF(OR(K32="",E32=""),"",ROUND((K32-E32)*86400,0)) | S32: =IF(OR(T32="",U32=""),"",T32-U32)
L33: =IF(OR(E33="",D33=""),"",ROUND((E33-D33)*86400,0)) | M33: =IF(OR(G33="",F33=""),"",ROUND((G33-F33)*86400,0)) | N33: =IF(OR(I33="",H33=""),"",ROUND((I33-H33)*86400,0)) | O33: =IF(OR(I33="",G33=""),"",ROUND((I33-G33)*86400,0)) | P33: =IF(OR(H33="",G33=""),"",ROUND((H33-G33)*86400,0)) | Q33: =IF(OR(J33="",I33=""),"",ROUND((J33-I33)*86400,0)) | R33: =IF(OR(K33="",E33=""),"",ROUND((K33-E33)*86400,0)) | S33: =IF(OR(T33="",U33=""),"",T33-U33)
L34: =IF(OR(E34="",D34=""),"",ROUND((E34-D34)*86400,0)) | M34: =IF(OR(G34="",F34=""),"",ROUND((G34-F34)*86400,0)) | N34: =IF(OR(I34="",H34=""),"",ROUND((I34-H34)*86400,0)) | O34: =IF(OR(I34="",G34=""),"",ROUND((I34-G34)*86400,0)) | P34: =IF(OR(H34="",G34=""),"",ROUND((H34-G34)*86400,0)) | Q34: =IF(OR(J34="",I34=""),"",ROUND((J34-I34)*86400,0)) | R34: =IF(OR(K34="",E34=""),"",ROUND((K34-E34)*86400,0)) | S34: =IF(OR(T34="",U34=""),"",T34-U34)
L35: =IF(OR(E35="",D35=""),"",ROUND((E35-D35)*86400,0)) | M35: =IF(OR(G35="",F35=""),"",ROUND((G35-F35)*86400,0)) | N35: =IF(OR(I35="",H35=""),"",ROUND((I35-H35)*86400,0)) | O35: =IF(OR(I35="",G35=""),"",ROUND((I35-G35)*86400,0)) | P35: =IF(OR(H35="",G35=""),"",ROUND((H35-G35)*86400,0)) | Q35: =IF(OR(J35="",I35=""),"",ROUND((J35-I35)*86400,0)) | R35: =IF(OR(K35="",E35=""),"",ROUND((K35-E35)*86400,0)) | S35: =IF(OR(T35="",U35=""),"",T35-U35)
L36: =IF(OR(E36="",D36=""),"",ROUND((E36-D36)*86400,0)) | M36: =IF(OR(G36="",F36=""),"",ROUND((G36-F36)*86400,0)) | N36: =IF(OR(I36="",H36=""),"",ROUND((I36-H36)*86400,0)) | O36: =IF(OR(I36="",G36=""),"",ROUND((I36-G36)*86400,0)) | P36: =IF(OR(H36="",G36=""),"",ROUND((H36-G36)*86400,0)) | Q36: =IF(OR(J36="",I36=""),"",ROUND((J36-I36)*86400,0)) | R36: =IF(OR(K36="",E36=""),"",ROUND((K36-E36)*86400,0)) | S36: =IF(OR(T36="",U36=""),"",T36-U36)
L37: =IF(OR(E37="",D37=""),"",ROUND((E37-D37)*86400,0)) | M37: =IF(OR(G37="",F37=""),"",ROUND((G37-F37)*86400,0)) | N37: =IF(OR(I37="",H37=""),"",ROUND((I37-H37)*86400,0)) | O37: =IF(OR(I37="",G37=""),"",ROUND((I37-G37)*86400,0)) | P37: =IF(OR(H37="",G37=""),"",ROUND((H37-G37)*86400,0)) | Q37: =IF(OR(J37="",I37=""),"",ROUND((J37-I37)*86400,0)) | R37: =IF(OR(K37="",E37=""),"",ROUND((K37-E37)*86400,0)) | S37: =IF(OR(T37="",U37=""),"",T37-U37)
L38: =IF(OR(E38="",D38=""),"",ROUND((E38-D38)*86400,0)) | M38: =IF(OR(G38="",F38=""),"",ROUND((G38-F38)*86400,0)) | N38: =IF(OR(I38="",H38=""),"",ROUND((I38-H38)*86400,0)) | O38: =IF(OR(I38="",G38=""),"",ROUND((I38-G38)*86400,0)) | P38: =IF(OR(H38="",G38=""),"",ROUND((H38-G38)*86400,0)) | Q38: =IF(OR(J38="",I38=""),"",ROUND((J38-I38)*86400,0)) | R38: =IF(OR(K38="",E38=""),"",ROUND((K38-E38)*86400,0)) | S38: =IF(OR(T38="",U38=""),"",T38-U38)
... L40: =IF(OR(E40="",D40=""),"",ROUND((E40-D40)*86400,0)) | M40: =IF(OR(G40="",F40=""),"",ROUND((G40-F40)*86400,0)) | N40: =IF(OR(I40="",H40=""),"",ROUND((I40-H40)*86400,0)) | O40: =IF(OR(I40="",G40=""),"",ROUND((I40-G40)*86400,0)) | P40: =IF(OR(H40="",G40=""),"",ROUND((H40-G40)*86400,0)) | Q40: =IF(OR(J40="",I40=""),"",ROUND((J40-I40)*86400,0)) | R40: =IF(OR(K40="",E40=""),"",ROUND((K40-E40)*86400,0)) | S40: =IF(OR(T40="",U40=""),"",T40-U40)
A42: ※ 히터 실제 OFF/ON은 히터 판넬 전류계(클램프미터) 또는 MC 동작음으로 확인. 열도달(T4)은 급기온도가 0.3℃ 이상 연속 상승 시작한 시각.
A43: ※ 스팀→전기: 중첩시간이 너무 짧으면(또는 음수) 급기온도 급락, 너무 길면 오버슈트 → 오버슈트 컬럼으로 함께 판단.

Sheet 4_초기개도_트렌드
A1: 4. 밸브 초기개도 / 램프 시험 트렌드 (1분 간격)
A2: 스팀 전환 직후 급기온도가 급격히 오르지 않는지 확인. 상승률이 허용치 초과 시 '초과' 표시 → 즉시 개도 낮추고 메모. 시험 1건당 블록 1개 사용, 결과는 '5_초기개도_매트릭스'에 옮겨 적음.
A4: 시험 블록 1 (예시)
A5: Test ID | B5: T-01 | C5: AHU | D5: AHU-G213 | E5: 급기 SP(℃) | F5: 20 | G5: 초기개도(%) | H5: 10 | I5: 램프율(%/분) | J5: 5 | K5: 허용 상승률(℃/분) | L5: 0.5
A6: 경과 (분) | B6: 시각 | C6: MV 지령 (%) | D6: MV 피드백 (%) | E6: 급기온도 (℃) | F6: 급기 상승률 (℃/분) | G6: 보관소 온도(℃) | H6: 보관소 습도(%) | I6: 헤더압력 (bar) | J6: 히터 ON 단수 | K6: 판정 | L6: 메모
A7: 0 | C7: 10 | D7: 10 | E7: 17.5 | F7: - | G7: 20 | H7: 45 | I7: 7.2 | J7: 0 | K7: =IF(OR(F7="",F7="-",$L$5=""),"",IF(F7>$L$5,"초과",IF(AND($F$5<>"",E7>$F$5+1),"오버슈트","OK")))
A8: 1 | C8: 15 | D8: 15 | E8: 17.6 | F8: =IF(OR(E8="",E7=""),"",E8-E7) -> 0.1 | G8: 20.02 | H8: 45 | I8: 7.2 | J8: 0 | K8: =IF(OR(F8="",F8="-",$L$5=""),"",IF(F8>$L$5,"초과",IF(AND($F$5<>"",E8>$F$5+1),"오버슈트","OK"))) -> OK
A9: 2 | C9: 20 | D9: 20 | E9: 17.9 | F9: =IF(OR(E9="",E8=""),"",E9-E8) -> 0.3 | G9: 20.04 | H9: 45 | I9: 7.2 | J9: 0 | K9: =IF(OR(F9="",F9="-",$L$5=""),"",IF(F9>$L$5,"초과",IF(AND($F$5<>"",E9>$F$5+1),"오버슈트","OK"))) -> OK
A10: 3 | C10: 25 | D10: 25 | E10: 18.4 | F10: =IF(OR(E10="",E9=""),"",E10-E9) -> 0.5 | G10: 20.06 | H10: 45 | I10: 7.2 | J10: 0 | K10: =IF(OR(F10="",F10="-",$L$5=""),"",IF(F10>$L$5,"초과",IF(AND($F$5<>"",E10>$F$5+1),"오버슈트","OK"))) -> OK
A11: 4 | C11: 30 | D11: 30 | E11: 18.9 | F11: =IF(OR(E11="",E10=""),"",E11-E10) -> 0.5 | G11: 20.08 | H11: 45 | I11: 7.2 | J11: 0 | K11: =IF(OR(F11="",F11="-",$L$5=""),"",IF(F11>$L$5,"초과",IF(AND($F$5<>"",E11>$F$5+1),"오버슈트","OK"))) -> OK
A12: 5 | C12: 35 | D12: 35 | E12: 19.3 | F12: =IF(OR(E12="",E11=""),"",E12-E11) -> 0.4 | G12: 20.1 | H12: 45 | I12: 7.2 | J12: 0 | K12: =IF(OR(F12="",F12="-",$L$5=""),"",IF(F12>$L$5,"초과",IF(AND($F$5<>"",E12>$F$5+1),"오버슈트","OK"))) -> OK
A13: 6 | C13: 35 | D13: 35 | E13: 19.7 | F13: =IF(OR(E13="",E12=""),"",E13-E12) -> 0.4 | G13: 20.12 | H13: 45 | I13: 7.2 | J13: 0 | K13: =IF(OR(F13="",F13="-",$L$5=""),"",IF(F13>$L$5,"초과",IF(AND($F$5<>"",E13>$F$5+1),"오버슈트","OK"))) -> OK
A14: 7 | C14: 33 | D14: 33 | E14: 20 | F14: =IF(OR(E14="",E13=""),"",E14-E13) -> 0.3 | G14: 20.14 | H14: 45 | I14: 7.2 | J14: 0 | K14: =IF(OR(F14="",F14="-",$L$5=""),"",IF(F14>$L$5,"초과",IF(AND($F$5<>"",E14>$F$5+1),"오버슈트","OK"))) -> OK
A15: 8 | C15: 30 | D15: 30 | E15: 20.2 | F15: =IF(OR(E15="",E14=""),"",E15-E14) -> 0.2 | G15: 20.16 | H15: 45 | I15: 7.2 | J15: 0 | K15: =IF(OR(F15="",F15="-",$L$5=""),"",IF(F15>$L$5,"초과",IF(AND($F$5<>"",E15>$F$5+1),"오버슈트","OK"))) -> OK
A16: 9 | C16: 28 | D16: 28 | E16: 20.3 | F16: =IF(OR(E16="",E15=""),"",E16-E15) -> 0.1 | G16: 20.18 | H16: 45 | I16: 7.2 | J16: 0 | K16: =IF(OR(F16="",F16="-",$L$5=""),"",IF(F16>$L$5,"초과",IF(AND($F$5<>"",E16>$F$5+1),"오버슈트","OK"))) -> OK
A17: 10 | C17: 28 | D17: 28 | E17: 20.2 | F17: =IF(OR(E17="",E16=""),"",E17-E16) -> -0.1 | G17: 20.2 | H17: 45 | I17: 7.2 | J17: 0 | K17: =IF(OR(F17="",F17="-",$L$5=""),"",IF(F17>$L$5,"초과",IF(AND($F$5<>"",E17>$F$5+1),"오버슈트","OK"))) -> OK
A18: 11 | F18: =IF(OR(E18="",E17=""),"",E18-E17) | K18: =IF(OR(F18="",F18="-",$L$5=""),"",IF(F18>$L$5,"초과",IF(AND($F$5<>"",E18>$F$5+1),"오버슈트","OK")))
A19: 12 | F19: =IF(OR(E19="",E18=""),"",E19-E18) | K19: =IF(OR(F19="",F19="-",$L$5=""),"",IF(F19>$L$5,"초과",IF(AND($F$5<>"",E19>$F$5+1),"오버슈트","OK")))
A20: 13 | F20: =IF(OR(E20="",E19=""),"",E20-E19) | K20: =IF(OR(F20="",F20="-",$L$5=""),"",IF(F20>$L$5,"초과",IF(AND($F$5<>"",E20>$F$5+1),"오버슈트","OK")))
A21: 14 | F21: =IF(OR(E21="",E20=""),"",E21-E20) | K21: =IF(OR(F21="",F21="-",$L$5=""),"",IF(F21>$L$5,"초과",IF(AND($F$5<>"",E21>$F$5+1),"오버슈트","OK")))
A22: 15 | F22: =IF(OR(E22="",E21=""),"",E22-E21) | K22: =IF(OR(F22="",F22="-",$L$5=""),"",IF(F22>$L$5,"초과",IF(AND($F$5<>"",E22>$F$5+1),"오버슈트","OK")))
A23: 16 | F23: =IF(OR(E23="",E22=""),"",E23-E22) | K23: =IF(OR(F23="",F23="-",$L$5=""),"",IF(F23>$L$5,"초과",IF(AND($F$5<>"",E23>$F$5+1),"오버슈트","OK")))
A24: 17 | F24: =IF(OR(E24="",E23=""),"",E24-E23) | K24: =IF(OR(F24="",F24="-",$L$5=""),"",IF(F24>$L$5,"초과",IF(AND($F$5<>"",E24>$F$5+1),"오버슈트","OK")))
A25: 18 | F25: =IF(OR(E25="",E24=""),"",E25-E24) | K25: =IF(OR(F25="",F25="-",$L$5=""),"",IF(F25>$L$5,"초과",IF(AND($F$5<>"",E25>$F$5+1),"오버슈트","OK")))
A26: 19 | F26: =IF(OR(E26="",E25=""),"",E26-E25) | K26: =IF(OR(F26="",F26="-",$L$5=""),"",IF(F26>$L$5,"초과",IF(AND($F$5<>"",E26>$F$5+1),"오버슈트","OK")))
A27: 20 | F27: =IF(OR(E27="",E26=""),"",E27-E26) | K27: =IF(OR(F27="",F27="-",$L$5=""),"",IF(F27>$L$5,"초과",IF(AND($F$5<>"",E27>$F$5+1),"오버슈트","OK")))
A28: 21 | F28: =IF(OR(E28="",E27=""),"",E28-E27) | K28: =IF(OR(F28="",F28="-",$L$5=""),"",IF(F28>$L$5,"초과",IF(AND($F$5<>"",E28>$F$5+1),"오버슈트","OK")))
A29: 22 | F29: =IF(OR(E29="",E28=""),"",E29-E28) | K29: =IF(OR(F29="",F29="-",$L$5=""),"",IF(F29>$L$5,"초과",IF(AND($F$5<>"",E29>$F$5+1),"오버슈트","OK")))
... A37: 30 | F37: =IF(OR(E37="",E36=""),"",E37-E36) | K37: =IF(OR(F37="",F37="-",$L$5=""),"",IF(F37>$L$5,"초과",IF(AND($F$5<>"",E37>$F$5+1),"오버슈트","OK")))
A38: 최대 상승률(℃/분) | B38: =IF(COUNT(F8:F37)=0,"",MAX(F8:F37)) -> 0.5 | C38: 최고 급기(℃) | D38: =IF(COUNT(E7:E37)=0,"",MAX(E7:E37)) -> 20.3 | E38: 오버슈트(℃) | F38: =IF(OR(F5="",COUNT(E7:E37)=0),"",MAX(E7:E37)-F5) -> 0.3 | G38: 보관소 온도변화(℃) | H38: =IF(COUNT(G7:G37)=0,"",MAX(G7:G37)-MIN(G7:G37)) -> 0.2 | I38: 초과 횟수 | J38: =COUNTIF(K7:K37,"초과") -> 0 | K38: 습도변화(%) | L38: =IF(COUNT(H7:H37)=0,"",MAX(H7:H37)-MIN(H7:H37)) -> 0
A40: 시험 블록 2
A41: Test ID | C41: AHU | E41: 급기 SP(℃) | G41: 초기개도(%) | I41: 램프율(%/분) | K41: 허용 상승률(℃/분)
A42: 경과 (분) | B42: 시각 | C42: MV 지령 (%) | D42: MV 피드백 (%) | E42: 급기온도 (℃) | F42: 급기 상승률 (℃/분) | G42: 보관소 온도(℃) | H42: 보관소 습도(%) | I42: 헤더압력 (bar) | J42: 히터 ON 단수 | K42: 판정 | L42: 메모
A43: 0 | F43: - | K43: =IF(OR(F43="",F43="-",$L$41=""),"",IF(F43>$L$41,"초과",IF(AND($F$41<>"",E43>$F$41+1),"오버슈트","OK")))
A44: 1 | F44: =IF(OR(E44="",E43=""),"",E44-E43) | K44: =IF(OR(F44="",F44="-",$L$41=""),"",IF(F44>$L$41,"초과",IF(AND($F$41<>"",E44>$F$41+1),"오버슈트","OK")))
A45: 2 | F45: =IF(OR(E45="",E44=""),"",E45-E44) | K45: =IF(OR(F45="",F45="-",$L$41=""),"",IF(F45>$L$41,"초과",IF(AND($F$41<>"",E45>$F$41+1),"오버슈트","OK")))
A46: 3 | F46: =IF(OR(E46="",E45=""),"",E46-E45) | K46: =IF(OR(F46="",F46="-",$L$41=""),"",IF(F46>$L$41,"초과",IF(AND($F$41<>"",E46>$F$41+1),"오버슈트","OK")))
A47: 4 | F47: =IF(OR(E47="",E46=""),"",E47-E46) | K47: =IF(OR(F47="",F47="-",$L$41=""),"",IF(F47>$L$41,"초과",IF(AND($F$41<>"",E47>$F$41+1),"오버슈트","OK")))
A48: 5 | F48: =IF(OR(E48="",E47=""),"",E48-E47) | K48: =IF(OR(F48="",F48="-",$L$41=""),"",IF(F48>$L$41,"초과",IF(AND($F$41<>"",E48>$F$41+1),"오버슈트","OK")))
A49: 6 | F49: =IF(OR(E49="",E48=""),"",E49-E48) | K49: =IF(OR(F49="",F49="-",$L$41=""),"",IF(F49>$L$41,"초과",IF(AND($F$41<>"",E49>$F$41+1),"오버슈트","OK")))
...

Sheet 5_초기개도_매트릭스
A1: 5. 초기개도율 최적화 매트릭스 (설정온도 × 초기개도율)
A2: 같은 AHU에서 초기개도율을 바꿔가며(예: 10→15→20%) 반복 시험. 판정 기준(아래 노란칸)을 모두 만족하는 조합 중 안정화 시간이 가장 짧은 값을 해당 설정온도의 초기개도로 채택. 외기온도 조건이 다르면 별도 행으로 기록.
A3: 허용 상승률(℃/분) | C3: 0.5 | D3: 허용 오버슈트(℃) | F3: 1 | G3: 보관소 허용변화(℃) | I3: 0.5 | J3: ← 가정치. 보관소 관리기준으로 수정
A5: Test ID | B5: AHU | C5: 날짜 | D5: 외기온도 (℃) | E5: 보관소 설정(℃) | F5: 급기 SP (℃) | G5: 전환 전 급기(℃) | H5: 초기개도 (%) | I5: 램프율 (%/분) | J5: 최대개도 제한(%) | K5: 최대 상승률 (℃/분) | L5: 오버슈트 (℃) | M5: 안정화 시간(분) | N5: 보관소 온도변화(℃) | O5: 열도달 시 개도(%) | P5: 판정 | Q5: 비고
A6: T-01 | B6: AHU-G213 | D6: 5 | E6: 20 | F6: 20 | G6: 17.5 | H6: 10 | I6: 5 | J6: 35 | K6: 0.5 | L6: 0.3 | M6: 9 | N6: 0.2 | O6: 15 | P6: =IF(OR(K6="",L6=""),"",IF(AND(K6<=$C$3,L6<=$F$3,OR(N6="",N6<=$I$3)),"적합","부적합")) -> 적합 | Q6: 예시 — 4_트렌드 블록1
P7: =IF(OR(K7="",L7=""),"",IF(AND(K7<=$C$3,L7<=$F$3,OR(N7="",N7<=$I$3)),"적합","부적합"))
P8: =IF(OR(K8="",L8=""),"",IF(AND(K8<=$C$3,L8<=$F$3,OR(N8="",N8<=$I$3)),"적합","부적합"))
P9: =IF(OR(K9="",L9=""),"",IF(AND(K9<=$C$3,L9<=$F$3,OR(N9="",N9<=$I$3)),"적합","부적합"))
P10: =IF(OR(K10="",L10=""),"",IF(AND(K10<=$C$3,L10<=$F$3,OR(N10="",N10<=$I$3)),"적합","부적합"))
P11: =IF(OR(K11="",L11=""),"",IF(AND(K11<=$C$3,L11<=$F$3,OR(N11="",N11<=$I$3)),"적합","부적합"))
P12: =IF(OR(K12="",L12=""),"",IF(AND(K12<=$C$3,L12<=$F$3,OR(N12="",N12<=$I$3)),"적합","부적합"))
P13: =IF(OR(K13="",L13=""),"",IF(AND(K13<=$C$3,L13<=$F$3,OR(N13="",N13<=$I$3)),"적합","부적합"))
P14: =IF(OR(K14="",L14=""),"",IF(AND(K14<=$C$3,L14<=$F$3,OR(N14="",N14<=$I$3)),"적합","부적합"))
P15: =IF(OR(K15="",L15=""),"",IF(AND(K15<=$C$3,L15<=$F$3,OR(N15="",N15<=$I$3)),"적합","부적합"))
P16: =IF(OR(K16="",L16=""),"",IF(AND(K16<=$C$3,L16<=$F$3,OR(N16="",N16<=$I$3)),"적합","부적합"))
P17: =IF(OR(K17="",L17=""),"",IF(AND(K17<=$C$3,L17<=$F$3,OR(N17="",N17<=$I$3)),"적합","부적합"))
P18: =IF(OR(K18="",L18=""),"",IF(AND(K18<=$C$3,L18<=$F$3,OR(N18="",N18<=$I$3)),"적합","부적합"))
... P25: =IF(OR(K25="",L25=""),"",IF(AND(K25<=$C$3,L25<=$F$3,OR(N25="",N25<=$I$3)),"적합","부적합"))
A28: 5-1. 설정온도별 채택 초기개도 (결론)
A29: AHU | B29: 급기 SP 15~18℃ | C29: 급기 SP 18~21℃ | D29: 급기 SP 21~24℃ | E29: 급기 SP 24℃~ | F29: 채택 램프율 (%/분) | G29: 최대개도 제한(%) | H29: 외기 조건 | Q29: 비고
A30: AHU-G203
A31: AHU-G204
A32: AHU-G213
A33: AHU-G301
A34: AHU-G107

Sheet 6_추가체크리스트
A1: 6. 추가 점검 체크리스트 (전환 로직 최적화 관련)
A2: 결과: OK / NG / N/A / 보류. 기준값은 일반적인 가정치이며 현장 기준에 맞춰 수정. ★ = 이번 조사에서 결정해야 할 사전 항목.
A4: No | B4: 구분 | C4: 점검 항목 | D4: 확인 방법 / 기준 | E4: 대상 AHU | F4: 결과 | G4: 측정값·내용 | H4: 조치 필요사항
A5: 1 | B5: 사전 결정★ | C5: 일반제동 헤더압력 일중 변화 → Pressure SP 결정 | D5: 현재 SP 10.0 bar는 임시값, 헤더 최고 약 8 bar. 1_파라메터기록 하단 프로파일 기록 후 주간 유지 가능한 압력으로 SP 결정 | E5: 일반제동
A6: 2 | B6: 사전 결정★ | C6: 세파제동 헤더압력 일중 변화 → Pressure SP 검증 | D6: 현재 SP 7.0 bar. 주간 유지 압력·최저 압력 확인 후 SP 적정성 판단 | E6: G107
A7: 3 | B7: 사전 결정★ | C7: SRC Override 운전 중인 AHU 상태 기록 | D7: 캡처 시 G204·G301·G107 Override(주황). 시험 전 상태 기록 → 시험 후 Enable(녹색) 원복 여부 결정 | E7: G204, G301, G107
A8: 4 | B8: 사전 결정★ | C8: Time Delay 입력 단위(초/분) 확인 | D8: 실측 권장값(초) 입력 시 단위 환산 필요 여부 | E8: 전체
A9: 5 | B9: 사전 결정★ | C9: Pressure Setpoint 하단 빨간 주석 내용 | D9: 주석 문구 기록 | E9: 전체
A10: 6 | B10: 계측 | C10: 헤더 압력계 현장 지시 vs UI (PRE-1, PRE-2) | D10: 편차 ≤ 0.2 bar | E10: 헤더
A11: 7 | B11: 계측 | C11: 급기온도 센서 현장 측정 vs UI | D11: 기준 온도계로 비교, 편차 ≤ 0.5℃ | E11: 전체
A12: 8 | B12: 계측 | C12: 히터 Command ↔ Status 피드백 일치 | D12: 단별 ON/OFF 지령 후 Status 표시 및 MC 동작 확인 | E12: 전체
A13: 9 | B13: 계측 | C13: Metasys 트렌드 로깅 설정 | D13: 헤더압력·급기온도·MV 지령/피드백·히터 단수, 5초~1분 간격 | E13: 전체
A14: 10 | B14: 전환 로직 | C14: 압력 SP 부근 헌팅(채터링) 여부 | D14: 1시간 내 전환 횟수 기록. 2회 초과 시 히스테리시스·확인지연 도입 | E14: 전체
A15: 11 | B15: 전환 로직 | C15: 다수 AHU 동시 스팀 전환 시 헤더압력 강하 | D15: 동시 전환 → 압력 강하폭 기록. 연쇄 복귀 발생 시 순차 전환 간격 적용 | E15: 일반제동
A16: 12 | B16: 전환 로직 | C16: 히터 일괄 OFF 시 급기온도 급락 | D16: 단계적 OFF(단당 지연) 필요성 판단 — 3_전환시간실측 최저 급기온도 | E16: 전체
... A38: 34 | B38: 에너지 | C38: 전력량(kWh) 및 스팀 사용량 기록 | D38: 전환 전·후 동일 조건 일간 사용량 비교 (절감효과 검증) | E38: 전체
B40: 집계 | C40: ="OK "&COUNTIF(F5:F38,"OK")&" / NG "&COUNTIF(F5:F38,"NG")&" / 보류 "&COUNTIF(F5:F38,"보류")&" / 미기록 "&COUNTBLANK(F5:F38) -> OK 0 / NG 0 / 보류 0 / 미기록 34

Sheet 7_로직개선제안
A1: 7. Metasys 전환 로직 개선 제안 파라메터
A2: 제안 초기값은 일반적인 시작점(가정치)이며 실측 후 '현장 결정값'에 확정. 특히 P04~P07은 '밸브를 0%에서 천천히 여는' 로직의 핵심.
A4: No | B4: 파라메터 | C4: 설명 / 목적 | D4: 제안 초기값 | E4: 단위 | F4: 조정 범위 | G4: 현장 결정값 | H4: 근거 시트 | I4: 반영 여부
A5: P01 | B5: 스팀 전환 압력 SP | C5: 헤더압력 ≥ SP → 스팀모드. 일반 10.0은 임시값(헤더 최고 약 8 bar) → 압력 프로파일로 결정 | D5: 8 미만 | E5: bar | F5: - | H5: 1_파라메터 1-1
A6: P02 | B6: 압력 히스테리시스 | C6: 전기 복귀 압력 = SP − 히스테리시스. SP 부근 잦은 전환(헌팅) 방지 | D6: 0.5 | E6: bar | F6: 0.3~1.0 | H6: 6_체크 #10
A7: P03 | B7: 압력 확인 지연 | C7: SP 이상이 연속 유지되어야 전환. 순간 압력 변동 무시 | D7: 60 | E7: 초 | F7: 30~180 | H7: 6_체크 #10
A8: P04 | B8: MV 초기개도 | C8: 전환 시작 시 밸브 시작 개도. 0%에서 시작하면 열도달이 늦고, 높으면 급승온 | D8: 10 | E8: % | F8: 0~30 | H8: 5_매트릭스
A9: P05 | B9: MV 램프율 | C9: 초기개도에서 목표 개도까지 분당 증가량 | D9: 5 | E9: %/분 | F9: 2~10 | H9: 4_트렌드
A10: P06 | B10: 전환 중 최대개도 제한 | C10: 램프 구간 동안 개도 상한. 전환 완료 후 PID 제어로 이관 | D10: 50 | E10: % | F10: 30~100 | H10: 4_트렌드
A11: P07 | B11: PID 이관 조건 | C11: 급기온도가 SP − Diff 도달 또는 램프 완료 시 PID 제어 시작 (Bumpless) | D11: SP−Diff | E11: ℃ | F11: - | H11: 4_트렌드
A12: P08 | B12: 히터 단계 OFF 간격 | C12: 스팀 열도달(T4) 확인 후 히터를 1단씩 순차 OFF — 급기온도 급락 방지 | D12: 30 | E12: 초/단 | F12: 10~120 | H12: 3_전환 A
A13: P09 | B13: Time Delay (열도달 대기) | C13: 전환신호 후 히터 OFF 시작까지 대기. 실측 스팀 총응답 + 여유 | D13: 실측 | E13: 초 | F13: - | H13: 3_전환 A / 8_최종
A14: P10 | B14: 최소 모드 유지시간 | C14: 전환 후 이 시간 동안 반대 모드 전환 금지 | D14: 10 | E14: 분 | F14: 5~30 | H14: 6_체크 #13
A15: P11 | B15: AHU 순차 전환 간격 | C15: 동일 헤더 공유 AHU를 시간차로 전환 — 헤더압력 급강하 방지 | D15: 120 | E15: 초 | F15: 60~300 | H15: 6_체크 #11
A16: P12 | B16: 스팀 실패 판정 | C16: MV ≥ 80% 인데 급기온도 < SP−2℃ 가 5분 지속 → 전기 복귀 + 알람 | D16: 80%/2℃/5분 | E16: - | F16: - | H16: 6_체크 #30
... A21: P17 | B21: 동절기 동파 보호 | C21: 외기 < 설정 시 코일 최소개도 또는 동파방지 서모스탯 연동 | D21: 외기 3℃ | E21: ℃ | F21: - | H21: 6_체크 #21
A23: ■ 제안 전환 시퀀스
A24: [전기→스팀] 압력 ≥ P01 이 P03 동안 유지 → (순차간격 P11 대기) → MV P04 개도 → P05 램프(상한 P06, 상승률 P14 초과 시 Hold) → 급기온도 상승(열도달) 확인 또는 P09 경과 → 히터 P08 간격으로 단계 OFF → P07 조건 시 PID 이관
A25: [스팀→전기] 압력 < P01 − P02 → 히터 단계 ON → P15 대기 → MV P16 속도로 닫힘 → 피드백 0% 확인
A26: [이상 시] P12 스팀 실패 또는 P13 상한 초과 → 즉시 전기모드 복귀 + 알람, P10 동안 재전환 금지

Sheet 8_최종세팅값
A1: 8. AHU별 최종 세팅값 요약
A2: 연두색은 3_전환시간실측(예시 행 포함)에서 자동 집계 — 예시 행을 지우거나 덮어쓴 뒤 사용. 노란색에 최종 확정값 기입.
A4: AHU | B4: 구분 | C4: A. 실측 횟수 (전기→스팀) | D4: 스팀 총응답 평균(초) | E4: 스팀 총응답 최대(초) | F4: 권장 Time Delay (최대+여유, 초) | G4: 열공백 최대 (초) | H4: B. 실측 횟수 (스팀→전기) | I4: 중첩시간 평균(초) | J4: 오버슈트 최대(℃) | K4: UI Time Delay As-left | L4: 최종 Time Delay | M4: 최종 초기개도(%) | N4: 최종 램프율 (%/분) | O4: 비고
A5: AHU-G203 | B5: 일반제동 | C5: =COUNTIFS(3_전환시간실측!$A$7:$A$21,A5,3_전환시간실측!$O$7:$O$21,">-99999") -> 0 | D5: =IFERROR(ROUND(AVERAGEIFS(3_전환시간실측!$O$7:$O$21,3_전환시간실측!$A$7:$A$21,A5),0),"") | E5: =IF(C5=0,"",_xlfn.MAXIFS(3_전환시간실측!$O$7:$O$21,3_전환시간실측!$A$7:$A$21,A5)) | F5: =IF(E5="","",E5+3_전환시간실측!$C$3) | G5: =IF(C5=0,"",_xlfn.MAXIFS(3_전환시간실측!$Q$7:$Q$21,3_전환시간실측!$A$7:$A$21,A5)) | H5: =COUNTIFS(3_전환시간실측!$A$26:$A$40,A5,3_전환시간실측!$O$26:$O$40,">-99999") -> 0 | I5: =IFERROR(ROUND(AVERAGEIFS(3_전환시간실측!$O$26:$O$40,3_전환시간실측!$A$26:$A$40,A5),0),"") | J5: =IF(H5=0,"",_xlfn.MAXIFS(3_전환시간실측!$S$26:$S$40,3_전환시간실측!$A$26:$A$40,A5)) | K5: =IF(1_파라메터기록!F13="","",1_파라메터기록!F13)
A6: AHU-G204 | B6: 일반제동 | C6: =COUNTIFS(3_전환시간실측!$A$7:$A$21,A6,3_전환시간실측!$O$7:$O$21,">-99999") -> 0 | D6: =IFERROR(ROUND(AVERAGEIFS(3_전환시간실측!$O$7:$O$21,3_전환시간실측!$A$7:$A$21,A6),0),"") | E6: =IF(C6=0,"",_xlfn.MAXIFS(3_전환시간실측!$O$7:$O$21,3_전환시간실측!$A$7:$A$21,A6)) | F6: =IF(E6="","",E6+3_전환시간실측!$C$3) | G6: =IF(C6=0,"",_xlfn.MAXIFS(3_전환시간실측!$Q$7:$Q$21,3_전환시간실측!$A$7:$A$21,A6)) | H6: =COUNTIFS(3_전환시간실측!$A$26:$A$40,A6,3_전환시간실측!$O$26:$O$40,">-99999") -> 0 | I6: =IFERROR(ROUND(AVERAGEIFS(3_전환시간실측!$O$26:$O$40,3_전환시간실측!$A$26:$A$40,A6),0),"") | J6: =IF(H6=0,"",_xlfn.MAXIFS(3_전환시간실측!$S$26:$S$40,3_전환시간실측!$A$26:$A$40,A6)) | K6: =IF(1_파라메터기록!H13="","",1_파라메터기록!H13)
A7: AHU-G213 | B7: 일반제동 | C7: =COUNTIFS(3_전환시간실측!$A$7:$A$21,A7,3_전환시간실측!$O$7:$O$21,">-99999") -> 1 | D7: =IFERROR(ROUND(AVERAGEIFS(3_전환시간실측!$O$7:$O$21,3_전환시간실측!$A$7:$A$21,A7),0),"") -> 95 | E7: =IF(C7=0,"",_xlfn.MAXIFS(3_전환시간실측!$O$7:$O$21,3_전환시간실측!$A$7:$A$21,A7)) -> 95 | F7: =IF(E7="","",E7+3_전환시간실측!$C$3) -> 125 | G7: =IF(C7=0,"",_xlfn.MAXIFS(3_전환시간실측!$Q$7:$Q$21,3_전환시간실측!$A$7:$A$21,A7)) -> 89 | H7: =COUNTIFS(3_전환시간실측!$A$26:$A$40,A7,3_전환시간실측!$O$26:$O$40,">-99999") -> 1 | I7: =IFERROR(ROUND(AVERAGEIFS(3_전환시간실측!$O$26:$O$40,3_전환시간실측!$A$26:$A$40,A7),0),"") -> 63 | J7: =IF(H7=0,"",_xlfn.MAXIFS(3_전환시간실측!$S$26:$S$40,3_전환시간실측!$A$26:$A$40,A7)) -> 2.1 | K7: =IF(1_파라메터기록!J13="","",1_파라메터기록!J13)
A8: AHU-G301 | B8: 일반제동 | C8: =COUNTIFS(3_전환시간실측!$A$7:$A$21,A8,3_전환시간실측!$O$7:$O$21,">-99999") -> 0 | D8: =IFERROR(ROUND(AVERAGEIFS(3_전환시간실측!$O$7:$O$21,3_전환시간실측!$A$7:$A$21,A8),0),"") | E8: =IF(C8=0,"",_xlfn.MAXIFS(3_전환시간실측!$O$7:$O$21,3_전환시간실측!$A$7:$A$21,A8)) | F8: =IF(E8="","",E8+3_전환시간실측!$C$3) | G8: =IF(C8=0,"",_xlfn.MAXIFS(3_전환시간실측!$Q$7:$Q$21,3_전환시간실측!$A$7:$A$21,A8)) | H8: =COUNTIFS(3_전환시간실측!$A$26:$A$40,A8,3_전환시간실측!$O$26:$O$40,">-99999") -> 0 | I8: =IFERROR(ROUND(AVERAGEIFS(3_전환시간실측!$O$26:$O$40,3_전환시간실측!$A$26:$A$40,A8),0),"") | J8: =IF(H8=0,"",_xlfn.MAXIFS(3_전환시간실측!$S$26:$S$40,3_전환시간실측!$A$26:$A$40,A8)) | K8: =IF(1_파라메터기록!L13="","",1_파라메터기록!L13)
A9: AHU-G107 | B9: 세파제동 | C9: =COUNTIFS(3_전환시간실측!$A$7:$A$21,A9,3_전환시간실측!$O$7:$O$21,">-99999") -> 0 | D9: =IFERROR(ROUND(AVERAGEIFS(3_전환시간실측!$O$7:$O$21,3_전환시간실측!$A$7:$A$21,A9),0),"") | E9: =IF(C9=0,"",_xlfn.MAXIFS(3_전환시간실측!$O$7:$O$21,3_전환시간실측!$A$7:$A$21,A9)) | F9: =IF(E9="","",E9+3_전환시간실측!$C$3) | G9: =IF(C9=0,"",_xlfn.MAXIFS(3_전환시간실측!$Q$7:$Q$21,3_전환시간실측!$A$7:$A$21,A9)) | H9: =COUNTIFS(3_전환시간실측!$A$26:$A$40,A9,3_전환시간실측!$O$26:$O$40,">-99999") -> 0 | I9: =IFERROR(ROUND(AVERAGEIFS(3_전환시간실측!$O$26:$O$40,3_전환시간실측!$A$26:$A$40,A9),0),"") | J9: =IF(H9=0,"",_xlfn.MAXIFS(3_전환시간실측!$S$26:$S$40,3_전환시간실측!$A$26:$A$40,A9)) | K9: =IF(1_파라메터기록!N13="","",1_파라메터기록!N13)
A11: ※ 권장 Time Delay 는 '초' 기준 — UI Time Delay 단위가 분이면 60으로 나눠 입력.
A12: ※ 열공백 최대가 크면(+) 히터 OFF가 너무 빠름 → Time Delay 증가 또는 단계 OFF 적용.
A14: 확인 서명
A15: 구분 | C15: 소속 | E15: 성명 | G15: 서명 | I15: 일자
A16: 점검자
A17: 제어(Metasys) 담당
A18: 설비 운영 담당
A19: 보관소 담당
